Workbook

Sheet Overview
A1: Category
A2: currency | B2: 0 | D2: rice | E2: 0 | G2: leadership | H2: 0
A3: soul_stone | B3: =B2+1 -> 1 | D3: gold | E3: =E2+1 -> 1 | G3: strength | H3: 1
A4: bundle | B4: =B3+1 -> 2 | D4: time_stone | E4: =E3+1 -> 2 | G4: intellect | H4: 2
A5: item | B5: =B4+1 -> 3 | D5: pocket_rice | E5: =E4+1 -> 3 | G5: politics | H5: 3
A6: treasure_piece | B6: =B5+1 -> 4 | D6: pocket_gold | E6: =E5+1 -> 4 | G6: charisma | H6: 4
A7: gacha_ticket | B7: =B6+1 -> 5 | D7: pocket_time_stone | E7: =E6+1 -> 5
A8: treasure | B8: =B7+1 -> 6 | D8: random_box_class_soul_stone | E8: =E7+1 -> 6
A9: contents_ticket | B9: =B8+1 -> 7 | D9: random_box_dedicated_soul_stone | E9: =E8+1 -> 7
D10: random_box_treasure_piece | E10: =E9+1 -> 8
D11: ticket_gacha_normal | E11: =E10+1 -> 9
D12: ticket_gacha_premium | E12: =E11+1 -> 10
D13: point_tournament | E13: =E12+1 -> 11
D14: point_raid | E14: =E13+1 -> 12
D15: public_soul_stone | E15: =E14+1 -> 13
D16: dedicated_soul_stone | E16: =E15+1 -> 14
D17: class_soul_stone | E17: =E16+1 -> 15
D18: treasure_mileage | E18: =E17+1 -> 16
D19: treasure_piece | E19: =E18+1 -> 17
D20: treasure | E20: =E19+1 -> 18
D21: ticket_tournament | E21: =E20+1 -> 19

Sheet s_item
A1: key | B1: #category | C1: category | D1: #type | E1: type | F1: value
A2: string | C2: int | E2: int | F2: string
A3: rice | B3: currency | C3: =VLOOKUP(B3,Overview!$A$2:$B$9,2,FALSE) -> 0 | D3: rice | E3: =VLOOKUP(D3,Overview!$D$2:$E$21,2,FALSE) -> 0
A4: gold | B4: currency | C4: =VLOOKUP(B4,Overview!$A$2:$B$9,2,FALSE) -> 0 | D4: gold | E4: =VLOOKUP(D4,Overview!$D$2:$E$21,2,FALSE) -> 1
A5: paid_gold | B5: currency | C5: =VLOOKUP(B5,Overview!$A$2:$B$9,2,FALSE) -> 0 | D5: gold | E5: =VLOOKUP(D5,Overview!$D$2:$E$21,2,FALSE) -> 1
A6: time_stone | B6: currency | C6: =VLOOKUP(B6,Overview!$A$2:$B$9,2,FALSE) -> 0 | D6: time_stone | E6: =VLOOKUP(D6,Overview!$D$2:$E$21,2,FALSE) -> 2
A7: rice_pocket_normal | B7: bundle | C7: =VLOOKUP(B7,Overview!$A$2:$B$9,2,FALSE) -> 2 | D7: pocket_rice | E7: =VLOOKUP(D7,Overview!$D$2:$E$21,2,FALSE) -> 3 | F7: rice_pocket_normal
A8: rice_pocket_elite | B8: bundle | C8: =VLOOKUP(B8,Overview!$A$2:$B$9,2,FALSE) -> 2 | D8: pocket_rice | E8: =VLOOKUP(D8,Overview!$D$2:$E$21,2,FALSE) -> 3 | F8: rice_pocket_elite
A9: rice_pocket_general | B9: bundle | C9: =VLOOKUP(B9,Overview!$A$2:$B$9,2,FALSE) -> 2 | D9: pocket_rice | E9: =VLOOKUP(D9,Overview!$D$2:$E$21,2,FALSE) -> 3 | F9: rice_pocket_general
A10: rice_pocket_hero | B10: bundle | C10: =VLOOKUP(B10,Overview!$A$2:$B$9,2,FALSE) -> 2 | D10: pocket_rice | E10: =VLOOKUP(D10,Overview!$D$2:$E$21,2,FALSE) -> 3 | F10: rice_pocket_hero
A11: rice_pocket_legend | B11: bundle | C11: =VLOOKUP(B11,Overview!$A$2:$B$9,2,FALSE) -> 2 | D11: pocket_rice | E11: =VLOOKUP(D11,Overview!$D$2:$E$21,2,FALSE) -> 3 | F11: rice_pocket_legend
A12: gold_pocket_normal | B12: bundle | C12: =VLOOKUP(B12,Overview!$A$2:$B$9,2,FALSE) -> 2 | D12: pocket_gold | E12: =VLOOKUP(D12,Overview!$D$2:$E$21,2,FALSE) -> 4 | F12: gold_pocket_normal
A13: gold_pocket_elite | B13: bundle | C13: =VLOOKUP(B13,Overview!$A$2:$B$9,2,FALSE) -> 2 | D13: pocket_gold | E13: =VLOOKUP(D13,Overview!$D$2:$E$21,2,FALSE) -> 4 | F13: gold_pocket_elite
A14: gold_pocket_general | B14: bundle | C14: =VLOOKUP(B14,Overview!$A$2:$B$9,2,FALSE) -> 2 | D14: pocket_gold | E14: =VLOOKUP(D14,Overview!$D$2:$E$21,2,FALSE) -> 4 | F14: gold_pocket_general
A15: gold_pocket_hero | B15: bundle | C15: =VLOOKUP(B15,Overview!$A$2:$B$9,2,FALSE) -> 2 | D15: pocket_gold | E15: =VLOOKUP(D15,Overview!$D$2:$E$21,2,FALSE) -> 4 | F15: gold_pocket_hero
A16: gold_pocket_legend | B16: bundle | C16: =VLOOKUP(B16,Overview!$A$2:$B$9,2,FALSE) -> 2 | D16: pocket_gold | E16: =VLOOKUP(D16,Overview!$D$2:$E$21,2,FALSE) -> 4 | F16: gold_pocket_legend
A17: time_stone_pocket_normal | B17: bundle | C17: =VLOOKUP(B17,Overview!$A$2:$B$9,2,FALSE) -> 2 | D17: pocket_time_stone | E17: =VLOOKUP(D17,Overview!$D$2:$E$21,2,FALSE) -> 5 | F17: time_stone_pocket_normal
A18: time_stone_pocket_elite | B18: bundle | C18: =VLOOKUP(B18,Overview!$A$2:$B$9,2,FALSE) -> 2 | D18: pocket_time_stone | E18: =VLOOKUP(D18,Overview!$D$2:$E$21,2,FALSE) -> 5 | F18: time_stone_pocket_elite
... A36: treasure_piece_random_box_legend | B36: bundle | C36: =VLOOKUP(B36,Overview!$A$2:$B$9,2,FALSE) -> 2 | D36: random_box_treasure_piece | E36: =VLOOKUP(D36,Overview!$D$2:$E$21,2,FALSE) -> 8 | F36: treasure_piece_random_box_legend
A37: normal_gacha_ticket | B37: gacha_ticket | C37: =VLOOKUP(B37,Overview!$A$2:$B$9,2,FALSE) -> 5 | D37: ticket_gacha_normal | E37: =VLOOKUP(D37,Overview!$D$2:$E$21,2,FALSE) -> 9
A38: premium_gacha_ticket | B38: gacha_ticket | C38: =VLOOKUP(B38,Overview!$A$2:$B$9,2,FALSE) -> 5 | D38: ticket_gacha_premium | E38: =VLOOKUP(D38,Overview!$D$2:$E$21,2,FALSE) -> 10
A39: raid_point | B39: currency | C39: =VLOOKUP(B39,Overview!$A$2:$B$9,2,FALSE) -> 0 | D39: point_raid | E39: =VLOOKUP(D39,Overview!$D$2:$E$21,2,FALSE) -> 12
A40: tournament_point | B40: currency | C40: =VLOOKUP(B40,Overview!$A$2:$B$9,2,FALSE) -> 0 | D40: point_tournament | E40: =VLOOKUP(D40,Overview!$D$2:$E$21,2,FALSE) -> 11
A41: public_soul_stone | B41: soul_stone | C41: =VLOOKUP(B41,Overview!$A$2:$B$9,2,FALSE) -> 1 | D41: public_soul_stone | E41: =VLOOKUP(D41,Overview!$D$2:$E$21,2,FALSE) -> 13
A42: dedicated_soul_stone_cao_cao | B42: soul_stone | C42: =VLOOKUP(B42,Overview!$A$2:$B$9,2,FALSE) -> 1 | D42: dedicated_soul_stone | E42: =VLOOKUP(D42,Overview!$D$2:$E$21,2,FALSE) -> 14 | F42: CaoCao
A43: dedicated_soul_stone_cao_ren | B43: soul_stone | C43: =VLOOKUP(B43,Overview!$A$2:$B$9,2,FALSE) -> 1 | D43: dedicated_soul_stone | E43: =VLOOKUP(D43,Overview!$D$2:$E$21,2,FALSE) -> 14 | F43: CaoRen
A44: dedicated_soul_stone_xiahou_dun | B44: soul_stone | C44: =VLOOKUP(B44,Overview!$A$2:$B$9,2,FALSE) -> 1 | D44: dedicated_soul_stone | E44: =VLOOKUP(D44,Overview!$D$2:$E$21,2,FALSE) -> 14 | F44: XiahouDun
A45: dedicated_soul_stone_zhang_liao | B45: soul_stone | C45: =VLOOKUP(B45,Overview!$A$2:$B$9,2,FALSE) -> 1 | D45: dedicated_soul_stone | E45: =VLOOKUP(D45,Overview!$D$2:$E$21,2,FALSE) -> 14 | F45: ZhangLiao
A46: dedicated_soul_stone_xiahou_yuan | B46: soul_stone | C46: =VLOOKUP(B46,Overview!$A$2:$B$9,2,FALSE) -> 1 | D46: dedicated_soul_stone | E46: =VLOOKUP(D46,Overview!$D$2:$E$21,2,FALSE) -> 14 | F46: XiahouYuan
A47: dedicated_soul_stone_xun_yu | B47: soul_stone | C47: =VLOOKUP(B47,Overview!$A$2:$B$9,2,FALSE) -> 1 | D47: dedicated_soul_stone | E47: =VLOOKUP(D47,Overview!$D$2:$E$21,2,FALSE) -> 14 | F47: XunYu
A48: dedicated_soul_stone_liu_bei | B48: soul_stone | C48: =VLOOKUP(B48,Overview!$A$2:$B$9,2,FALSE) -> 1 | D48: dedicated_soul_stone | E48: =VLOOKUP(D48,Overview!$D$2:$E$21,2,FALSE) -> 14 | F48: LiuBei
A49: dedicated_soul_stone_guan_yu | B49: soul_stone | C49: =VLOOKUP(B49,Overview!$A$2:$B$9,2,FALSE) -> 1 | D49: dedicated_soul_stone | E49: =VLOOKUP(D49,Overview!$D$2:$E$21,2,FALSE) -> 14 | F49: GuanYu
A50: dedicated_soul_stone_zhang_fei | B50: soul_stone | C50: =VLOOKUP(B50,Overview!$A$2:$B$9,2,FALSE) -> 1 | D50: dedicated_soul_stone | E50: =VLOOKUP(D50,Overview!$D$2:$E$21,2,FALSE) -> 14 | F50: ZhangFei
A51: dedicated_soul_stone_zhao_yun | B51: soul_stone | C51: =VLOOKUP(B51,Overview!$A$2:$B$9,2,FALSE) -> 1 | D51: dedicated_soul_stone | E51: =VLOOKUP(D51,Overview!$D$2:$E$21,2,FALSE) -> 14 | F51: ZhaoYun
A52: dedicated_soul_stone_huang_zhong | B52: soul_stone | C52: =VLOOKUP(B52,Overview!$A$2:$B$9,2,FALSE) -> 1 | D52: dedicated_soul_stone | E52: =VLOOKUP(D52,Overview!$D$2:$E$21,2,FALSE) -> 14 | F52: HuangZhong
A53: dedicated_soul_stone_zhuge_liang | B53: soul_stone | C53: =VLOOKUP(B53,Overview!$A$2:$B$9,2,FALSE) -> 1 | D53: dedicated_soul_stone | E53: =VLOOKUP(D53,Overview!$D$2:$E$21,2,FALSE) -> 14 | F53: ZhugeLiang
... A67: class_soul_stone_strategist | B67: soul_stone | C67: =VLOOKUP(B67,Overview!$A$2:$B$9,2,FALSE) -> 1 | D67: class_soul_stone | E67: =VLOOKUP(D67,Overview!$D$2:$E$21,2,FALSE) -> 15 | F67: strategist
A68: treasure_mileage | B68: currency | C68: =VLOOKUP(B68,Overview!$A$2:$B$9,2,FALSE) -> 0 | D68: treasure_mileage | E68: =VLOOKUP(D68,Overview!$D$2:$E$21,2,FALSE) -> 16
A69: treasure_piece_liutao | B69: treasure_piece | C69: =VLOOKUP(B69,Overview!$A$2:$B$9,2,FALSE) -> 4 | D69: treasure_piece | E69: =VLOOKUP(D69,Overview!$D$2:$E$21,2,FALSE) -> 17 | F69: liutao
A70: treasure_piece_sanlue | B70: treasure_piece | C70: =VLOOKUP(B70,Overview!$A$2:$B$9,2,FALSE) -> 4 | D70: treasure_piece | E70: =VLOOKUP(D70,Overview!$D$2:$E$21,2,FALSE) -> 17 | F70: sanlue
...

Sheet s_treasure
A1: key | B1: #name | C1: #stat | D1: stat | E1: effect | F1: pieces_required
A2: string | B2: string | C2: enum castle_stat_type | D2: int | E2: string | F2: int
A3: liutao | B3: 육도 | C3: leadership | D3: =VLOOKUP(C3,Overview!$G$2:$H$6,2,) -> 0 | F3: 20
A4: sanlue | B4: 삼략 | C4: leadership | D4: =VLOOKUP(C4,Overview!$G$2:$H$6,2,) -> 0 | F4: 20
A5: weiliaozi | B5: 위료자 | C5: leadership | D5: =VLOOKUP(C5,Overview!$G$2:$H$6,2,) -> 0 | F5: 20
A6: commanders_banner | B6: 장수기 | C6: leadership | D6: =VLOOKUP(C6,Overview!$G$2:$H$6,2,) -> 0 | F6: 20
A7: tiger_tally | B7: 호부 | C7: leadership | D7: =VLOOKUP(C7,Overview!$G$2:$H$6,2,) -> 0 | F7: 20
A8: war_drum_gong | B8: 금고 | C8: leadership | D8: =VLOOKUP(C8,Overview!$G$2:$H$6,2,) -> 0 | F8: 20
A9: sima_fa | B9: 사마법 | C9: leadership | D9: =VLOOKUP(C9,Overview!$G$2:$H$6,2,) -> 0 | F9: 20
A10: wuzi | B10: 오자 | C10: leadership | D10: =VLOOKUP(C10,Overview!$G$2:$H$6,2,) -> 0 | F10: 20
A11: red_cliff_flame | B11: 적벽의 화염 | C11: strength | D11: =VLOOKUP(C11,Overview!$G$2:$H$6,2,) -> 1 | E11: {"boss_damage":1,"attack_speed":1} | F11: 20
A12: bangcheonhwagug_shard | B12: 방천화극 파편 | C12: strength | D12: =VLOOKUP(C12,Overview!$G$2:$H$6,2,) -> 1 | E12: {"attack_speed":1,"boss_damage":1} | F12: 20
A13: ganjiang_moye | B13: 간장막야 | C13: strength | D13: =VLOOKUP(C13,Overview!$G$2:$H$6,2,) -> 1 | F13: 20
A14: chungou | B14: 순구 | C14: strength | D14: =VLOOKUP(C14,Overview!$G$2:$H$6,2,) -> 1 | F14: 20
A15: zhanlu | B15: 담로 | C15: strength | D15: =VLOOKUP(C15,Overview!$G$2:$H$6,2,) -> 1 | F15: 20
A16: yuchang | B16: 어장 | C16: strength | D16: =VLOOKUP(C16,Overview!$G$2:$H$6,2,) -> 1 | F16: 20
A17: taie | B17: 태아 | C17: strength | D17: =VLOOKUP(C17,Overview!$G$2:$H$6,2,) -> 1 | F17: 20
A18: juque | B18: 거궐 | C18: strength | D18: =VLOOKUP(C18,Overview!$G$2:$H$6,2,) -> 1 | F18: 20
A19: shengxie | B19: 승영 | C19: strength | D19: =VLOOKUP(C19,Overview!$G$2:$H$6,2,) -> 1 | F19: 20
A20: lords_war_bow | B20: 군왕궁 | C20: strength | D20: =VLOOKUP(C20,Overview!$G$2:$H$6,2,) -> 1 | F20: 20
A21: wujangwon_star | B21: 오장원의 별 | C21: intellect | D21: =VLOOKUP(C21,Overview!$G$2:$H$6,2,) -> 2 | E21: {"cooldown_rate":1,"move_speed":1,"life_steal":1} | F21: 20
A22: art_of_war | B22: 손자병법 | C22: intellect | D22: =VLOOKUP(C22,Overview!$G$2:$H$6,2,) -> 2 | F22: 20
A23: qimen_dunjia | B23: 기문둔갑 | C23: intellect | D23: =VLOOKUP(C23,Overview!$G$2:$H$6,2,) -> 2 | F23: 20
A24: i_ching | B24: 주역 | C24: intellect | D24: =VLOOKUP(C24,Overview!$G$2:$H$6,2,) -> 2 | F24: 20
A25: guiguzi | B25: 귀곡자 | C25: intellect | D25: =VLOOKUP(C25,Overview!$G$2:$H$6,2,) -> 2 | F25: 20
A26: guanzi | B26: 관자 | C26: intellect | D26: =VLOOKUP(C26,Overview!$G$2:$H$6,2,) -> 2 | F26: 20
A27: han_feizi | B27: 한비자 | C27: intellect | D27: =VLOOKUP(C27,Overview!$G$2:$H$6,2,) -> 2 | F27: 20
A28: su_shu_of_huangshi | B28: 황석공소서 | C28: intellect | D28: =VLOOKUP(C28,Overview!$G$2:$H$6,2,) -> 2 | F28: 20
A29: mozi | B29: 묵자 | C29: intellect | D29: =VLOOKUP(C29,Overview!$G$2:$H$6,2,) -> 2 | F29: 20
A30: emperors_seal | B30: 황제의 인장 | C30: politics | D30: =VLOOKUP(C30,Overview!$G$2:$H$6,2,) -> 3 | E30: {"attack_speed":1,"critical_rate":1,"critical_damage":1} | F30: 20
A31: book_of_lord_shang | B31: 상군서 | C31: politics | D31: =VLOOKUP(C31,Overview!$G$2:$H$6,2,) -> 3 | F31: 20
A32: lushi_chunqiu | B32: 여씨춘추 | C32: politics | D32: =VLOOKUP(C32,Overview!$G$2:$H$6,2,) -> 3 | F32: 20
A33: analects | B33: 논어 | C33: politics | D33: =VLOOKUP(C33,Overview!$G$2:$H$6,2,) -> 3 | F33: 20
A34: wei_administrative_code | B34: 정전 | C34: politics | D34: =VLOOKUP(C34,Overview!$G$2:$H$6,2,) -> 3 | F34: 20
A35: stratagems_of_warring_states | B35: 전국책 | C35: politics | D35: =VLOOKUP(C35,Overview!$G$2:$H$6,2,) -> 3 | F35: 20
A36: imperial_jade_seal | B36: 옥새 | C36: politics | D36: =VLOOKUP(C36,Overview!$G$2:$H$6,2,) -> 3 | F36: 20
A37: prefects_official_seal | B37: 군목 인장 | C37: politics | D37: =VLOOKUP(C37,Overview!$G$2:$H$6,2,) -> 3 | F37: 20
A38: huanglao_silk_manuscript | B38: 황노백서 | C38: politics | D38: =VLOOKUP(C38,Overview!$G$2:$H$6,2,) -> 3 | F38: 20
A39: doewon_cup | B39: 도원의 술잔 | C39: charisma | D39: =VLOOKUP(C39,Overview!$G$2:$H$6,2,) -> 4 | E39: {"life_steal":1,"move_speed":1} | F39: 20
A40: hes_jade_disc | B40: 화씨벽 | C40: charisma | D40: =VLOOKUP(C40,Overview!$G$2:$H$6,2,) -> 4 | F40: 20
...
